<mujoco model="louis">

  <!-- physics -->
  <option timestep="0.002" gravity="0 0 -9.81"/>

  <visual>
    <headlight ambient="0.4 0.4 0.4"/>
  </visual>

  <default>
    <default class="louis">
      <joint axis="0 0 1"/>
      <default class="hip_rot">
        <joint armature="0.005" frictionloss="0.3" damping="2" range="-0.6 0.6"/>
      </default>
      <default class="hip_abd">
        <joint armature="0.005" frictionloss="0.3" damping="2" range="-0.4 0.4"/>
      </default>
      <default class="hip_flex">
        <joint armature="0.007" frictionloss="0.3" damping="2" range="-1.7 0.5"/>
      </default>
      <default class="knee">
        <joint armature="0.005" frictionloss="1.0" damping="3" range="0 2.0"/>
      </default>
      <default class="ankle_flex">
        <joint armature="0.005" frictionloss="1.0" damping="2" range="-0.5 0.7"/>
      </default>
      <default class="ankle_rot">
        <joint armature="0.0005" frictionloss="0.1" damping="0.5" range="-0.5 0.5"/>
      </default>
      <default class="visual">
        <geom contype="0" conaffinity="0" density="0"/>
      </default>
    </default>
  </default>

  <asset>
    <texture type="skybox" builtin="gradient"
             rgb1="0.3 0.5 0.7" rgb2="0 0 0" width="512" height="512"/>
    <texture name="ground" type="2d" builtin="checker"
             rgb1="0.8 0.8 0.8" rgb2="0.6 0.6 0.6"
             width="512" height="512"/>
    <material name="ground"    texture="ground" texrepeat="10 10"/>
    <material name="body"      rgba="0.75 0.45 0.10 1"/>
    <material name="joint"     rgba="0.20 0.15 0.08 1"/>
    <material name="leg"       rgba="0.65 0.38 0.08 1"/>
    <material name="foot"      rgba="0.15 0.12 0.08 1"/>
    <material name="hydraulic" rgba="0.55 0.50 0.45 1"/>
    <material name="rivet"     rgba="0.85 0.80 0.70 1"/>
  </asset>

  <worldbody>

    <geom name="floor" type="plane" size="50 50 0.1"
          material="ground" condim="3" friction="1.0 0.005 0.0001"/>
    <light name="sun" pos="0 0 10" dir="0 0 -1"
           diffuse="0.8 0.8 0.8" specular="0.3 0.3 0.3"/>

    <body name="torso" childclass="louis" pos="0 0 0.90">
      <freejoint/>

      <geom name="torso" type="box" size="0.14 0.20 0.13" material="body" density="1000"/>

      <!-- torso details -->
      <geom class="visual" type="box" size="0.005 0.14 0.08" pos=" 0.141 0.0 0.02" material="leg"/>
      <geom class="visual" type="box" size="0.005 0.14 0.08" pos="-0.141 0.0 0.02" material="leg"/>
      <geom class="visual" type="sphere" size="0.012" pos=" 0.142  0.12  0.10" material="rivet"/>
      <geom class="visual" type="sphere" size="0.012" pos=" 0.142 -0.12  0.10" material="rivet"/>
      <geom class="visual" type="sphere" size="0.012" pos="-0.142  0.12  0.10" material="rivet"/>
      <geom class="visual" type="sphere" size="0.012" pos="-0.142 -0.12  0.10" material="rivet"/>
      <geom class="visual" type="sphere" size="0.012" pos=" 0.142  0.12 -0.06" material="rivet"/>
      <geom class="visual" type="sphere" size="0.012" pos=" 0.142 -0.12 -0.06" material="rivet"/>
      <geom class="visual" type="sphere" size="0.012" pos="-0.142  0.12 -0.06" material="rivet"/>
      <geom class="visual" type="sphere" size="0.012" pos="-0.142 -0.12 -0.06" material="rivet"/>

      <!-- ===== LEFT LEG ===== -->
      <body name="LL_hip_rot" pos="0 0.20 -0.10">
        <joint name="LL_HR" class="hip_rot" axis="0 0 1"/>
        <geom type="sphere" size="0.07" material="joint"/>

        <body name="LL_hip_abd" pos="0 0 0">
          <inertial pos="0 0 0" mass="0.05" diaginertia="0.0001 0.0001 0.0001"/>
          <joint name="LL_HAA" class="hip_abd" axis="0 1 0"/>

          <body name="LL_hip_flex" pos="0 0 -0.02">
            <joint name="LL_HF" class="hip_flex" axis="1 0 0"/>

            <geom name="left_thigh" type="capsule" size="0.055"
                  fromto="0 0 0 0 0 -0.30" material="leg"/>
            <geom class="visual" type="capsule" size="0.018"
                  fromto="0.07 0 -0.02 0.07 0 -0.25" material="hydraulic"/>
            <geom class="visual" type="sphere" size="0.022"
                  pos="0.07 0 -0.02" material="joint"/>
            <geom type="sphere" size="0.065" pos="0 0 -0.30" material="joint"/>

            <body name="LL_knee" pos="0 0 -0.30">
              <joint name="LL_KFE" class="knee" axis="0 -1 0"/>

              <geom name="left_shin" type="capsule" size="0.045"
                    fromto="0 0 0 0 0 -0.26" material="leg"/>
              <geom class="visual" type="capsule" size="0.014"
                    fromto="0.065 0 -0.02 0.065 0 -0.20" material="hydraulic"/>
              <geom class="visual" type="sphere" size="0.018"
                    pos="0.065 0 -0.02" material="joint"/>
              <geom type="sphere" size="0.055" pos="0 0 -0.26" material="joint"/>

              <body name="LL_ankle_flex" pos="0 0 -0.26">
                <inertial pos="0 0 0" mass="0.05" diaginertia="0.0001 0.0001 0.0001"/>
                <joint name="LL_AFE" class="ankle_flex" axis="1 0 0"/>

                <body name="LL_ankle_rot" pos="0 0 0">
                  <joint name="LL_FAA" class="ankle_rot" axis="0 1 0"/>
                  <geom name="left_foot" type="box"
                        size="0.10 0.06 0.03" pos="0.02 0 -0.03"
                        material="foot" friction="1.5 0.005 0.0001"/>
                  <geom class="visual" type="sphere" size="0.009" pos=" 0.08  0.05 -0.01" material="rivet"/>
                  <geom class="visual" type="sphere" size="0.009" pos=" 0.08 -0.05 -0.01" material="rivet"/>
                  <geom class="visual" type="sphere" size="0.009" pos="-0.05  0.05 -0.01" material="rivet"/>
                  <geom class="visual" type="sphere" size="0.009" pos="-0.05 -0.05 -0.01" material="rivet"/>
                </body>
              </body>
            </body>
          </body>
        </body>
      </body>

      <!-- ===== RIGHT LEG ===== -->
      <body name="LR_hip_rot" pos="0 -0.20 -0.10">
        <joint name="LR_HR" class="hip_rot" axis="0 0 1"/>
        <geom type="sphere" size="0.07" material="joint"/>

        <body name="LR_hip_abd" pos="0 0 0">
          <inertial pos="0 0 0" mass="0.05" diaginertia="0.0001 0.0001 0.0001"/>
          <joint name="LR_HAA" class="hip_abd" axis="0 1 0"/>

          <body name="LR_hip_flex" pos="0 0 -0.02">
            <joint name="LR_HF" class="hip_flex" axis="1 0 0"/>

            <geom name="right_thigh" type="capsule" size="0.055"
                  fromto="0 0 0 0 0 -0.30" material="leg"/>
            <geom class="visual" type="capsule" size="0.018"
                  fromto="0.07 0 -0.02 0.07 0 -0.25" material="hydraulic"/>
            <geom class="visual" type="sphere" size="0.022"
                  pos="0.07 0 -0.02" material="joint"/>
            <geom type="sphere" size="0.065" pos="0 0 -0.30" material="joint"/>

            <body name="LR_knee" pos="0 0 -0.30">
              <joint name="LR_KFE" class="knee" axis="0 1 0"/>

              <geom name="right_shin" type="capsule" size="0.045"
                    fromto="0 0 0 0 0 -0.26" material="leg"/>
              <geom class="visual" type="capsule" size="0.014"
                    fromto="0.065 0 -0.02 0.065 0 -0.20" material="hydraulic"/>
              <geom class="visual" type="sphere" size="0.018"
                    pos="0.065 0 -0.02" material="joint"/>
              <geom type="sphere" size="0.055" pos="0 0 -0.26" material="joint"/>

              <body name="LR_ankle_flex" pos="0 0 -0.26">
                <inertial pos="0 0 0" mass="0.05" diaginertia="0.0001 0.0001 0.0001"/>
                <joint name="LR_AFE" class="ankle_flex" axis="1 0 0"/>

                <body name="LR_ankle_rot" pos="0 0 0">
                  <joint name="LR_FAA" class="ankle_rot" axis="0 1 0"/>
                  <geom name="right_foot" type="box"
                        size="0.10 0.06 0.03" pos="0.02 0 -0.03"
                        material="foot" friction="1.5 0.005 0.0001"/>
                  <geom class="visual" type="sphere" size="0.009" pos=" 0.08  0.05 -0.01" material="rivet"/>
                  <geom class="visual" type="sphere" size="0.009" pos=" 0.08 -0.05 -0.01" material="rivet"/>
                  <geom class="visual" type="sphere" size="0.009" pos="-0.05  0.05 -0.01" material="rivet"/>
                  <geom class="visual" type="sphere" size="0.009" pos="-0.05 -0.05 -0.01" material="rivet"/>
                </body>
              </body>
            </body>
          </body>
        </body>
      </body>

    </body>
  </worldbody>

  <!-- ===== ACTUATORS:
       ctrlrange matches each joint's range exactly so the policy can
       only command physically valid targets. kp/kv tuned per joint:
       - bigger joints (hip flex, knee) get higher kp
       - distal joints (ankle rot) get lower kp to avoid jitter
  -->
  <actuator>
    <position name="LL_HR"  joint="LL_HR"  kp="120" kv="6"  ctrlrange="-0.6 0.6"/>
    <position name="LL_HAA" joint="LL_HAA" kp="120" kv="6"  ctrlrange="-0.4 0.4"/>
    <position name="LL_HF"  joint="LL_HF"  kp="200" kv="10" ctrlrange="-1.7 0.5"/>
    <position name="LL_KFE" joint="LL_KFE" kp="200" kv="10" ctrlrange="0 2.0"/>
    <position name="LL_AFE" joint="LL_AFE" kp="80"  kv="4"  ctrlrange="-0.5 0.7"/>
    <position name="LL_FAA" joint="LL_FAA" kp="40"  kv="2"  ctrlrange="-0.5 0.5"/>

    <position name="LR_HR"  joint="LR_HR"  kp="120" kv="6"  ctrlrange="-0.6 0.6"/>
    <position name="LR_HAA" joint="LR_HAA" kp="120" kv="6"  ctrlrange="-0.4 0.4"/>
    <position name="LR_HF"  joint="LR_HF"  kp="200" kv="10" ctrlrange="-1.7 0.5"/>
    <position name="LR_KFE" joint="LR_KFE" kp="200" kv="10" ctrlrange="0 2.0"/>
    <position name="LR_AFE" joint="LR_AFE" kp="80"  kv="4"  ctrlrange="-0.5 0.7"/>
    <position name="LR_FAA" joint="LR_FAA" kp="40"  kv="2"  ctrlrange="-0.5 0.5"/>
  </actuator>

  <keyframe>
    <key name="stand"
      qpos="0 0 0.90 1 0 0 0
            0 0 0 0 0 0
            0 0 0 0 0 0"/>
  </keyframe>

</mujoco>