<mujoco model="louis">

  <!-- physics settings -->
  <option timestep="0.002" gravity="0 0 -9.81"/>

  <!-- visual settings -->
  <visual>
    <headlight ambient="0.4 0.4 0.4"/>
  </visual>

  <!-- materials -->
  <asset>
    <texture type="skybox" builtin="gradient"
             rgb1="0.3 0.5 0.7" rgb2="0 0 0" width="512" height="512"/>
    <texture name="ground" type="2d" builtin="checker"
             rgb1="0.8 0.8 0.8" rgb2="0.6 0.6 0.6"
             width="512" height="512"/>
    <material name="ground" texture="ground" texrepeat="10 10"/>
    <material name="body"   rgba="0.8 0.8 0.8 1"/>  <!-- silver -->
    <material name="joint"  rgba="0.1 0.1 0.1 1"/>  <!-- black joints -->
    <material name="leg"    rgba="0.7 0.7 0.7 1"/>  <!-- light gray legs -->
    <material name="foot"   rgba="0.1 0.1 0.1 1"/>  <!-- black feet -->
    <material name="eye_yellow"  rgba="0.85 0.80 0.20 1"/>
    <material name="mouth_dark"  rgba="0.12 0.10 0.08 1"/>
    <material name="teeth"       rgba="0.90 0.85 0.55 1"/>
  </asset>

  <!-- the world -->
  <worldbody>

    <!-- ground plane -->
    <geom name="floor" type="plane" size="50 50 0.1"
          material="ground" condim="3" friction="1.0 0.005 0.0001"/>

    <!-- lighting -->
    <light name="sun" pos="0 0 10" dir="0 0 -1"
           diffuse="0.8 0.8 0.8" specular="0.2 0.2 0.2"/>

    <!-- ===== LOUIS BODY ===== -->
    <body name="torso" pos="0 0 0.70">

      <!-- free joint lets torso move freely in the world -->
      <freejoint name="root"/>

      <!-- sphere torso -->
      <geom name="torso" type="sphere" size="0.18"
            material="body" density="1000"/>

      <!-- facial features  -->
      <geom name="antenna_stem" type="cylinder" size="0.008 0.055" pos="0.0 0.0 0.245" material="joint"     contype="0" conaffinity="0" density="0"/>
      <geom name="antenna_tip"  type="sphere"   size="0.016"       pos="0.0 0.0 0.305" material="joint"     contype="0" conaffinity="0" density="0"/>
      <geom name="left_eye"  type="box" size="0.018 0.032 0.025" pos="0.158  0.062  0.048" material="eye_yellow" contype="0" conaffinity="0" density="0"/>
      <geom name="right_eye" type="box" size="0.018 0.032 0.025" pos="0.158 -0.062  0.048" material="eye_yellow" contype="0" conaffinity="0" density="0"/>
      <geom name="mouth" type="box" size="0.018 0.085 0.022" pos="0.160 0.0 -0.055" material="mouth_dark"   contype="0" conaffinity="0" density="0"/>
      <geom name="tooth_1" type="box" size="0.012 0.016 0.014" pos="0.168  0.055 -0.048" material="teeth"   contype="0" conaffinity="0" density="0"/>
      <geom name="tooth_2" type="box" size="0.012 0.016 0.014" pos="0.168  0.018 -0.048" material="teeth"   contype="0" conaffinity="0" density="0"/>
      <geom name="tooth_3" type="box" size="0.012 0.016 0.014" pos="0.168 -0.018 -0.048" material="teeth"   contype="0" conaffinity="0" density="0"/>
      <geom name="tooth_4" type="box" size="0.012 0.016 0.014" pos="0.168 -0.055 -0.048" material="teeth"   contype="0" conaffinity="0" density="0"/>

      <!-- black joint balls at hip attachment points -->
      <geom name="left_hip_ball"  type="sphere" size="0.05"
            pos="0 0.18 -0.1" material="joint"/>
      <geom name="right_hip_ball" type="sphere" size="0.05"
            pos="0 -0.18 -0.1" material="joint"/>

      <!-- ===== LEFT LEG ===== -->
      <body name="left_thigh" pos="0 0.18 -0.1">
        <joint name="left_hip" type="hinge"
               axis="1 0 0" range="-60 60"
               damping="2" stiffness="0"/>
        <geom name="left_thigh" type="capsule"
              size="0.03" fromto="0 0 0 0.2 0.05 -0.25"
              material="leg"/>
        <geom name="left_knee_ball" type="sphere" size="0.04"
              pos="0.2 0.05 -0.25" material="joint"/>

        <body name="left_shin" pos="0.2 0.05 -0.25">
          <joint name="left_knee" type="hinge"
                 axis="1 0 0" range="-120 0"
                 damping="2" stiffness="0"/>
          <geom name="left_shin" type="capsule"
                size="0.025" fromto="0 0 0 -0.15 -0.05 -0.25"
                material="leg"/>

          <body name="left_foot" pos="-0.15 -0.05 -0.25">
            <joint name="left_ankle" type="hinge"
                   axis="1 0 0" range="-45 45"
                   damping="1" stiffness="0"/>
            <geom name="left_foot" type="box"
                  size="0.08 0.05 0.02" pos="0 0 -0.02"
                  material="foot" friction="1.5 0.005 0.0001"/>
          </body>
        </body>
      </body>

      <!-- ===== RIGHT LEG ===== -->
      <body name="right_thigh" pos="0 -0.18 -0.1">
        <joint name="right_hip" type="hinge"
               axis="1 0 0" range="-60 60"
               damping="2" stiffness="0"/>
        <geom name="right_thigh" type="capsule"
              size="0.03" fromto="0 0 0 0.2 -0.05 -0.25"
              material="leg"/>
        <geom name="right_knee_ball" type="sphere" size="0.04"
              pos="0.2 -0.05 -0.25" material="joint"/>

        <body name="right_shin" pos="0.2 -0.05 -0.25">
          <joint name="right_knee" type="hinge"
                 axis="1 0 0" range="-120 0"
                 damping="2" stiffness="0"/>
          <geom name="right_shin" type="capsule"
                size="0.025" fromto="0 0 0 -0.15 0.05 -0.25"
                material="leg"/>

          <body name="right_foot" pos="-0.15 0.05 -0.25">
            <joint name="right_ankle" type="hinge"
                   axis="1 0 0" range="-45 45"
                   damping="1" stiffness="0"/>
            <geom name="right_foot" type="box"
                  size="0.08 0.05 0.02" pos="0 0 -0.02"
                  material="foot" friction="1.5 0.005 0.0001"/>
          </body>
        </body>
      </body>

    </body>
  </worldbody>

  <!-- ===== ACTUATORS ===== -->
  <actuator>
    <motor name="left_hip"    joint="left_hip"    gear="150" ctrlrange="-1 1"/>
    <motor name="left_knee"   joint="left_knee"   gear="150" ctrlrange="-1 1"/>
    <motor name="left_ankle"  joint="left_ankle"  gear="100" ctrlrange="-1 1"/>
    <motor name="right_hip"   joint="right_hip"   gear="150" ctrlrange="-1 1"/>
    <motor name="right_knee"  joint="right_knee"  gear="150" ctrlrange="-1 1"/>
    <motor name="right_ankle" joint="right_ankle" gear="100" ctrlrange="-1 1"/>
  </actuator>

  <keyframe>
    <key name="stand" qpos="0 0 0.70 1 0 0 0 0 0 0 0 0 0"/>
  </keyframe>

</mujoco>